2025-08-23 10:03:41,492 - rag_piece - INFO - setup_logging:61 - Logging initialized - Level: INFO, File: logs\rag_piece_20250823_100341.log
2025-08-23 10:03:41,494 - rag_piece - INFO - main:315 - Starting article summarizer test
2025-08-23 10:03:43,767 - rag_piece - ERROR - main:354 - Error during summarization test: 1 validation error for RefineDocumentsChain
initial_response_name
  Field required [type=missing, input_value={'initial_llm_chain': LLM...le_name': 'context_str'}, input_type=dict]
    For further information visit https://errors.pydantic.dev/2.11/v/missing
Traceback (most recent call last):
  File "C:\Users\liav korem\Desktop\AI Course\RAG-Piece\article_summarizer.py", line 319, in main
    summarizer = ArticleSummarizer(max_chunk_size=400)
  File "C:\Users\liav korem\Desktop\AI Course\RAG-Piece\article_summarizer.py", line 109, in __init__
    self.refine_chain = RefineDocumentsChain(
  File "C:\Users\liav korem\AppData\Local\Programs\Python\Python39\lib\site-packages\langchain_core\_api\deprecation.py", line 222, in warn_if_direct_instance
    return wrapped(self, *args, **kwargs)
  File "C:\Users\liav korem\AppData\Local\Programs\Python\Python39\lib\site-packages\langchain_core\load\serializable.py", line 130, in __init__
    super().__init__(*args, **kwargs)
  File "C:\Users\liav korem\AppData\Local\Programs\Python\Python39\lib\site-packages\pydantic\main.py", line 253, in __init__
    validated_self = self.__pydantic_validator__.validate_python(data, self_instance=self)
pydantic_core._pydantic_core.ValidationError: 1 validation error for RefineDocumentsChain
initial_response_name
  Field required [type=missing, input_value={'initial_llm_chain': LLM...le_name': 'context_str'}, input_type=dict]
    For further information visit https://errors.pydantic.dev/2.11/v/missing
